Workbook

Sheet SALES TRACKER
A2: PRODUCT DESCRIPTION | B2: JL RETAILS | C2: B&Q RETAILS | D2: TOTAL STOCK | E2: INVENTORY | F2: STOCK CHECK 03.08
A3: Heavy Duty Storage Box - 270L / Taupe | B3: 75 | C3: 59 | D3: 320 | E3: =D3-AB21-AB40 | F3: 70
A4: Heavy Duty Storage Box - 450L / Taupe | B4: 145 | C4: 129 | D4: 225 | E4: =D4-AB22-AB41 | F4: 9
A5: Heavy Duty Storage Box - 680L / Black | B5: 175 | C5: 149 | D5: 166 | E5: =D5-AB23-AB42 | F5: 26
A6: Heavy Duty Storage Box - 680L / Taupe | B6: 175 | C6: 149 | D6: 260 | E6: =D6-AB24-AB43 | F6: 1
A7: Heavy Duty Storage Box - 870L / Black | B7: 215 | C7: 179 | D7: 177 | E7: =D7-AB25-AB44 | F7: 0
A8: Heavy Duty Storage Box - 870L / Taupe | B8: 215 | C8: 179 | D8: 185 | E8: =D8-AB26-AB45 | F8: 25
A9: Heavy Duty Storage Box - 980L / Black | B9: 235 | C9: 199 | D9: 235 | E9: =D9-AB27-AB46 | F9: 33
A10: Heavy Duty Storage Box - 980L / Taupe | B10: 235 | C10: 199 | D10: 220 | E10: =D10-AB28-AB47 | F10: 0
A11: L Premium Metal Storage Box - 683L / Green | B11: 399 | C11: 349 | D11: 30 | E11: =D11-AB29-AB48
A12: L Premium Metal Storage Box - 683L / Grey | B12: 399 | C12: 349 | D12: 30 | E12: =D12-AB30-AB49
A13: XL Premium Metal Storage Box - 1056L / Green | B13: 499 | C13: 449 | D13: 30 | E13: =D13-AB31-AB50
A14: XL Premium Metal Storage Box - 1056L / Grey | B14: 499 | C14: 449 | D14: 30 | E14: =D14-AB32-AB51
A15: 3m Luxury Hydraulic Parasol with 45kg Base and Cover - Grey | B15: 265 | C15: 179 | D15: 50 | E15: =D15-AB33-AB52
A16: 3m Luxury Hydraulic Parasol with 45kg Base and Cover - Natural | B16: 265 | C16: 179 | D16: 50 | E16: =D16-AB34-AB53
A17: Premium Pop Up Gazebo With Sides | B17: 199 | C17: 179 | D17: 100 | E17: =D17-AB35-AB54
A19: JOHN LEWIS | B19: MARCH | F19: APRIL | K19: MAY | O19: JUNE | T19: JULY | X19: AUGUST
A20: PRODUCT DESCRIPTION | B20: 1st - 8th March | C20: 9th - 15th March | D20: 16th - 22nd March | E20: 23rd - 31st March | F20: 1st - 5th April | G20: 6th-12th April | H20: 13th - 19th April | I20: 20th - 26th April | J20: 27th April - 3rd May | K20: 4th - 10th May | L20: 11th - 17th May | M20: 18th - 24th May | N20: 25th - 31st May | O20: 1st-7th June | P20: 8th-14th June | Q20: 15th-21st June | R20: 22nd-28th June | S20: 29th June-5th July | T20: 6th - 12th July | U20: 13th - 19th July | V20: 20th - 26th July | W20: 27th July - 2nd Aug | X20: 3rd-9th Aug | Y20: 10th-16th Aug | Z20: 17th-23rd Aug | AA20: 24th-30th Aug | AB20: TOTAL
A21: Heavy Duty Storage Box - 270L / Taupe | J21: 2 | K21: 9 | L21: 9 | M21: 8 | N21: 18 | O21: 19 | P21: 13 | Q21: 21 | R21: 19 | S21: 13 | T21: 23 | U21: 10 | V21: 16 | AB21: =SUM(B21:AA21) | AD21: =O21+P21+Q21+R21 | AE21: =O40+P40+Q40+R40 | AF21: =AD21+AE21
A22: Heavy Duty Storage Box - 450L / Taupe | J22: 1 | K22: 6 | L22: 14 | M22: 10 | N22: 18 | O22: 19 | P22: 14 | Q22: 7 | R22: 18 | S22: 23 | T22: 11 | U22: 9 | V22: 6 | AB22: =SUM(B22:AA22) | AD22: =O22+P22+Q22+R22 | AE22: =O41+P41+Q41+R41 | AF22: =AD22+AE22
A23: Heavy Duty Storage Box - 680L / Black | J23: 0 | K23: 0 | L23: 3 | M23: 7 | N23: 9 | O23: 13 | P23: 2 | Q23: 0 | R23: 0 | S23: 0 | T23: 4 | U23: 2 | V23: 2 | AB23: =SUM(B23:AA23) | AD23: =O23+P23+Q23+R23 | AE23: =O42+P42+Q42+R42 | AF23: =AD23+AE23
A24: Heavy Duty Storage Box - 680L / Taupe | J24: 1 | K24: 6 | L24: 3 | M24: 9 | N24: 18 | O24: 19 | P24: 29 | Q24: 17 | R24: 9 | S24: 0 | T24: 8 | U24: 22 | V24: 9 | AB24: =SUM(B24:AA24) | AD24: =O24+P24+Q24+R24 | AE24: =O43+P43+Q43+R43 | AF24: =AD24+AE24
A25: Heavy Duty Storage Box - 870L / Black | J25: 0 | K25: 2 | L25: 3 | M25: 0 | N25: 0 | O25: 0 | P25: 0 | Q25: 0 | R25: 0 | S25: 0 | T25: 1 | U25: 2 | V25: 2 | AB25: =SUM(B25:AA25) | AD25: =O25+P25+Q25+R25 | AE25: =O44+P44+Q44+R44 | AF25: =AD25+AE25
A26: Heavy Duty Storage Box - 870L / Taupe | J26: 4 | K26: 2 | L26: 6 | M26: 10 | N26: 2 | O26: 0 | P26: 0 | Q26: 0 | R26: 0 | S26: 0 | T26: 5 | U26: 5 | V26: 5 | AB26: =SUM(B26:AA26) | AD26: =O26+P26+Q26+R26 | AE26: =O45+P45+Q45+R45 | AF26: =AD26+AE26
A27: Heavy Duty Storage Box - 980L / Black | J27: 5 | K27: 4 | L27: 2 | M27: 4 | N27: 3 | O27: 0 | P27: 0 | Q27: 0 | R27: 0 | S27: 0 | T27: 7 | U27: 1 | V27: 2 | AB27: =SUM(B27:AA27) | AD27: =O27+P27+Q27+R27 | AE27: =O46+P46+Q46+R46 | AF27: =AD27+AE27
A28: Heavy Duty Storage Box - 980L / Taupe | J28: 4 | K28: 6 | L28: 13 | M28: 13 | N28: 6 | O28: 0 | P28: 0 | Q28: 0 | R28: 0 | S28: 0 | T28: 20 | U28: 11 | V28: 10 | AB28: =SUM(B28:AA28) | AD28: =O28+P28+Q28+R28 | AE28: =O47+P47+Q47+R47 | AF28: =AD28+AE28
A29: L Premium Metal Storage Box - 683L / Green | J29: 0 | K29: 2 | L29: 2 | M29: 2 | N29: 1 | O29: 4 | P29: 1 | Q29: 0 | R29: 0 | S29: 0 | T29: 0 | U29: 1 | V29: 2 | AB29: =SUM(B29:AA29) | AD29: =O29+P29+Q29+R29 | AE29: =O48+P48+Q48+R48 | AF29: =AD29+AE29
A30: L Premium Metal Storage Box - 683L / Grey | J30: 0 | K30: 1 | L30: 1 | M30: 0 | N30: 0 | O30: 1 | P30: 1 | Q30: 1 | R30: 3 | S30: 3 | T30: 4 | U30: 4 | V30: 0 | AB30: =SUM(B30:AA30) | AD30: =O30+P30+Q30+R30 | AE30: =O49+P49+Q49+R49 | AF30: =AD30+AE30
A31: XL Premium Metal Storage Box - 1056L / Green | J31: 0 | K31: 1 | L31: 3 | M31: 2 | N31: 2 | O31: 1 | P31: 3 | Q31: 2 | R31: 4 | S31: 0 | T31: 1 | U31: 1 | V31: 5 | AB31: =SUM(B31:AA31) | AD31: =O31+P31+Q31+R31 | AE31: =O50+P50+Q50+R50 | AF31: =AD31+AE31
A32: XL Premium Metal Storage Box - 1056L / Grey | J32: 2 | K32: 0 | L32: 0 | M32: 2 | N32: 0 | O32: 0 | P32: 0 | Q32: 0 | R32: 4 | S32: 2 | T32: 7 | U32: 2 | V32: 2 | AB32: =SUM(B32:AA32) | AD32: =O32+P32+Q32+R32 | AE32: =O51+P51+Q51+R51 | AF32: =AD32+AE32
... A35: Premium Pop Up Gazebo With Sides | J35: 0 | K35: 2 | L35: 0 | M35: 5 | N35: 3 | O35: 3 | P35: 1 | Q35: 11 | R35: 6 | S35: 5 | T35: 9 | U35: 6 | V35: 3 | AB35: =SUM(B35:AA35) | AD35: =O35+P35+Q35+R35 | AE35: =O54+P54+Q54+R54 | AF35: =AD35+AE35
A36: TOTAL | B36: =SUM(B21:B28) | C36: =SUM(C21:C28) | D36: =SUM(D21:D28) | E36: =SUM(E21:E28) | F36: =SUM(F21:F28) | G36: =SUM(G21:G28) | H36: =SUM(H21:H28) | I36: =SUM(I21:I28) | J36: =SUM(J21:J35) | K36: =SUM(K21:K35) | L36: =SUM(L21:L35) | M36: =SUM(M21:M35) | N36: =SUM(N21:N35) | O36: =SUM(O21:O35) | P36: =SUM(P21:P35) | Q36: =SUM(Q21:Q35) | ... AB36: =SUM(AB21:AB35)
A38: B&Q MARKETPLACE | B38: MARCH | F38: APRIL | K38: MAY | O38: JUNE | T38: JULY | X38: AUGUST
A39: PRODUCT DESCRIPTION | B39: 1st - 8th March | C39: 9th - 15th March | D39: 16th - 22nd March | E39: 23rd - 29th March | F39: 30th March - 5th April | G39: 6th-12th April | H39: 13th - 19th April | I39: 20th - 26th April | J39: 27th April - 3rd May | K39: 4th - 10th May | L39: 11th - 17th May | M39: 18th - 24th May | N39: 25th - 31st May | O39: 1st-7th June | P39: 8th-14th June | Q39: 15th-21st June | R39: 22nd-28th June | S39: 29th June-5th July | T39: 6th - 12th July | U39: 13th - 19th July | V39: 20th - 26th July | W39: 27th July - 2nd Aug | X39: 3rd-9th Aug | Y39: 10th-16th Aug | Z39: 17th-23rd Aug | AA39: 24th-30th Aug | AB39: TOTAL | AD39: OVERALL TOTAL SOLD
A40: Heavy Duty Storage Box - 270L / Taupe | C40: 1 | D40: 1 | E40: 0 | F40: 2 | G40: 1 | H40: 3 | I40: 1 | J40: 2 | K40: 2 | L40: 3 | M40: 5 | N40: 2 | O40: 2 | P40: 3 | Q40: 6 | R40: 3 | S40: 5 | T40: 2 | U40: 6 | V40: 3 | AB40: =SUM(B40:AA40) | AD40: =AB21+AB40
A41: Heavy Duty Storage Box - 450L / Taupe | C41: 0 | D41: 2 | E41: 2 | F41: 2 | G41: 1 | H41: 2 | I41: 1 | J41: 3 | K41: 4 | L41: 1 | M41: 3 | N41: 3 | O41: 3 | P41: 6 | Q41: 2 | R41: 3 | S41: 0 | T41: 1 | U41: 2 | V41: 2 | AB41: =SUM(B41:AA41) | AD41: =AB22+AB41
A42: Heavy Duty Storage Box - 680L / Black | C42: 0 | D42: 1 | E42: 1 | F42: 1 | G42: 3 | H42: 4 | I42: 2 | J42: 3 | K42: 3 | L42: 5 | M42: 4 | N42: 20 | O42: 10 | P42: 4 | Q42: 2 | R42: 0 | S42: 0 | T42: 7 | U42: 2 | V42: 10 | AB42: =SUM(B42:AA42) | AD42: =AB23+AB42
A43: Heavy Duty Storage Box - 680L / Taupe | C43: 0 | D43: 1 | E43: 2 | F43: 0 | G43: 2 | H43: 2 | I43: 5 | J43: 6 | K43: 8 | L43: 4 | M43: 5 | N43: 11 | O43: 7 | P43: 3 | Q43: 13 | R43: 6 | S43: 2 | T43: 4 | U43: 6 | V43: 8 | AB43: =SUM(B43:AA43) | AD43: =AB24+AB43
A44: Heavy Duty Storage Box - 870L / Black | C44: 0 | D44: 0 | E44: 2 | F44: 4 | G44: 11 | H44: 8 | I44: 22 | J44: 11 | K44: 4 | L44: 5 | M44: 0 | N44: 0 | O44: 0 | P44: 0 | Q44: 0 | R44: 0 | S44: 4 | T44: 5 | U44: 10 | V44: 14 | W44: 25 | AB44: =SUM(B44:AA44) | AD44: =AB25+AB44
A45: Heavy Duty Storage Box - 870L / Taupe | C45: 0 | D45: 1 | E45: 2 | F45: 0 | G45: 4 | H45: 5 | I45: 10 | J45: 6 | K45: 14 | L45: 18 | M45: 6 | N45: 2 | O45: 0 | P45: 0 | Q45: 6 | R45: 0 | S45: 6 | T45: 1 | U45: 5 | V45: 9 | AB45: =SUM(B45:AA45) | AD45: =AB26+AB45
...

Sheet Sheet1

Sheet INVENTORY
A1: Product Name | B1: Account Name | C1: Qty Sold | D1: Total Qty Sold | E1: Total Qty Purchased | F1: Inventory | H1: Shop | I1: Stock Update 19.05 | J1: Stock Update 29.05 | K1: Stock Update 16.06
A2: Heavy Duty Storage Box - 270L / Taupe | B2: B&Q Marketplace | C2: ='SALES TRACKER'!AB40 | D2: =C2+C3 | E2: 320 | F2: =E2-D2 | H2: B&Q Marketplace | I2: 100 | J2: 100 | K2: 100
B3: John Lewis D2C | C3: ='SALES TRACKER'!AB21 | H3: John Lewis D2C | I3: 183 | J3: 169 | K3: 114
A4: Heavy Duty Storage Box - 450L / Taupe | B4: B&Q Marketplace | C4: ='SALES TRACKER'!AB41 | D4: =C4+C5 | E4: 225 | F4: =E4-D4 | H4: B&Q Marketplace | I4: 86 | J4: 84 | K4: 50
B5: John Lewis D2C | C5: ='SALES TRACKER'!AB22 | H5: John Lewis D2C | I5: 100 | J5: 84 | K5: 60
A6: Heavy Duty Storage Box - 680L / Black | B6: B&Q Marketplace | C6: ='SALES TRACKER'!AB42 | D6: 99 | E6: 99 | F6: =E6-D6 | H6: B&Q Marketplace | I6: 37 | J6: 29 | K6: 3
B7: John Lewis D2C | C7: ='SALES TRACKER'!AB23 | H7: John Lewis D2C | I7: 37 | J7: 30 | K7: 0
A8: Heavy Duty Storage Box - 680L / Taupe | B8: B&Q Marketplace | C8: ='SALES TRACKER'!AB43 | D8: =C8+C9 | E8: 180 | F8: =E8-D8 | H8: B&Q Marketplace | I8: 70 | J8: 50 | K8: 20
B9: John Lewis D2C | C9: ='SALES TRACKER'!AB24 | H9: John Lewis D2C | I9: 69 | J9: 66 | K9: 23
A10: Heavy Duty Storage Box - 870L / Black | B10: B&Q Marketplace | C10: ='SALES TRACKER'!AB44 | D10: =C10+C11 | E10: 67 | F10: =E10-D10 | H10: B&Q Marketplace | I10: 0 | J10: 0 | K10: 0
B11: John Lewis D2C | C11: ='SALES TRACKER'!AB25 | H11: John Lewis D2C | I11: 21 | J11: 0 | K11: 0
A12: Heavy Duty Storage Box - 870L / Taupe | B12: B&Q Marketplace | C12: ='SALES TRACKER'!AB45 | D12: =C12+C13 | E12: 100 | F12: =E12-D12 | H12: B&Q Marketplace | I12: 5 | J12: 5 | K12: 6
B13: John Lewis D2C | C13: ='SALES TRACKER'!AB26 | H13: John Lewis D2C | I13: 28 | J13: 6 | K13: 0
A14: Heavy Duty Storage Box - 980L / Black | B14: B&Q Marketplace | C14: ='SALES TRACKER'!AB46 | D14: =C14+C15 | E14: 100 | F14: =E14-D14 | H14: B&Q Marketplace | I14: 5 | J14: 2 | K14: 5
B15: John Lewis D2C | C15: ='SALES TRACKER'!AB27 | H15: John Lewis D2C | I15: 25 | J15: 6 | K15: 0
A16: Heavy Duty Storage Box - 980L / Taupe | B16: B&Q Marketplace | C16: ='SALES TRACKER'!AB47 | D16: =C16+C17 | E16: 100 | F16: =E16-D16 | H16: B&Q Marketplace | I16: 0 | J16: 0 | K16: 0
B17: John Lewis D2C | C17: ='SALES TRACKER'!AB28 | H17: John Lewis D2C | I17: 19 | J17: 0 | K17: 0
A18: L Premium Metal Storage Box - 683L / Green | B18: B&Q Marketplace | C18: ='SALES TRACKER'!AB48 | D18: =C18+C19 | E18: 30 | F18: =E18-D18 | H18: B&Q Marketplace | I18: 5 | J18: 8 | K18: 5
B19: John Lewis D2C | C19: ='SALES TRACKER'!AB29 | H19: John Lewis D2C | I19: 20 | J19: 15 | K19: 7
A20: L Premium Metal Storage Box - 683L / Grey | B20: B&Q Marketplace | C20: ='SALES TRACKER'!AB49 | D20: =C20+C21 | E20: 30 | F20: =E20-D20 | H20: B&Q Marketplace | I20: 9 | J20: 14 | K20: 10
B21: John Lewis D2C | C21: ='SALES TRACKER'!AB32 | H21: John Lewis D2C | I21: 20 | J21: 15 | K21: 16
A22: XL Premium Metal Storage Box - 1056L / Green | B22: B&Q Marketplace | C22: ='SALES TRACKER'!AB50 | D22: =C22+C23 | E22: 30 | F22: =E22-D22 | H22: B&Q Marketplace | I22: 6 | J22: 9 | K22: 7
B23: John Lewis D2C | C23: ='SALES TRACKER'!AB31 | H23: John Lewis D2C | I23: 20 | J23: 15 | K23: 10
A24: XL Premium Metal Storage Box - 1056L / Grey | B24: B&Q Marketplace | C24: ='SALES TRACKER'!AB51 | D24: =C24+C25 | E24: 30 | F24: =E24-D24 | H24: B&Q Marketplace | I24: 8 | J24: 11 | K24: 10
B25: John Lewis D2C | C25: ='SALES TRACKER'!AB32 | H25: John Lewis D2C | I25: 20 | J25: 15 | K25: 15
A26: 3m Luxury Hydraulic Parasol with 45kg Base and Cover - Grey | B26: B&Q Marketplace | C26: ='SALES TRACKER'!AB52 | D26: =C26+C27 | E26: 50 | F26: =E26-D26 | H26: B&Q Marketplace | I26: 47 | J26: 40 | K26: 10
B27: John Lewis D2C | C27: ='SALES TRACKER'!AB33 | H27: John Lewis D2C | I27: 50 | J27: 49 | K27: 13
A28: 3m Luxury Hydraulic Parasol with 45kg Base and Cover - Natural | B28: B&Q Marketplace | C28: ='SALES TRACKER'!AB53 | D28: =C28+C29 | E28: 50 | F28: =E28-D28 | H28: B&Q Marketplace | I28: 46 | J28: 40 | K28: 10
B29: John Lewis D2C | C29: ='SALES TRACKER'!AB34 | H29: John Lewis D2C | I29: 50 | J29: 40 | K29: 14
A30: Premium Pop Up Gazebo With Sides | B30: B&Q Marketplace | C30: ='SALES TRACKER'!AB54 | D30: =C30+C31 | E30: 100 | F30: =E30-D30 | H30: B&Q Marketplace | I30: 45 | J30: 42 | K30: 20
B31: John Lewis D2C | C31: ='SALES TRACKER'!AB35 | H31: John Lewis D2C | I31: 50 | J31: 50 | K31: 24

Sheet CANCELLED ORDERS
A1: JOHN LEWIS
A2: PRODUCT DESCRIPTION | B2: CUSTOMER NAME | C2: ORDER NUMBER | D2: PURCHASE DATE | E2: QTY | F2: COMMENTS
A3: Heavy Duty Storage Box - 870L / Black | B3: Mrs Hunter | C3: 160193245 | D3: 17/05/2026 | E3: 1 | F3: Out of stock, customer happy to accept exchange for 980L Black, stock updated -1 870L Black and +1 980L Black
A4: Heavy Duty Storage Box - 980L / Taupe | B4: Mrs Hennesy | C4: 160347814 | D4: 46167 | E4: 1
A5: Heavy Duty Storage Box - 980L / Taupe | B5: Mrs Campbell | C5: 160352196 | D5: 46167 | E5: 1
A6: Heavy Duty Storage Box - 980L / Taupe | B6: Mrs Radley | C6: 160364081 | D6: 46167 | E6: 1
A7: Heavy Duty Storage Box - 980L / Taupe | B7: Mrs Millington | C7: 160364047 | D7: 46167 | E7: 1
A8: Heavy Duty Storage Box - 980L / Taupe | B8: Mr Mintey | C8: 160363974 | D8: 46167 | E8: 1
A10: B&Q MARKETPLACE
A11: PRODUCT DESCRIPTION | B11: CUSTOMER NAME | C11: ORDER NUMBER | D11: PURCHASE DATE | E11: QTY | F11: COMMENTS
A12: Heavy Duty Storage Box - 870L / Black | B12: Miss Charlotte Bentley | C12: 1063882487-A | D12: 14/05/2026 | E12: 2 | F12: Out of stock, customer asked for refund, stock updated -2 (weekly units sold 8, updated to 6)
A13: Heavy Duty Storage Box - 870L / Black | B13: Philip Steele | C13: 1063993668-A | D13: 17/05/2026 | E13: 1 | F13: Out of stock, customer asked for refund, stock updated -1 (weekly units sold 6, updated to 5)
A14: Heavy Duty Storage Box - 870L / Black | B14: Balwant Samra | C14: 1063877643-A | D14: 14/05/2026 | E14: 1 | F14: Out of stock, awaiting customer reply, offered refund or exchange
A15: Heavy Duty Storage Box - 870L / Black | B15: Mr Andrew Gooding | C15: 1063967778-A | D15: 46158 | E15: 1 | F15: Out of stock, customer happy to accept exchange for 870L Taupe, stock updated -1 870L Black and +1 870L Taupe
A16: Heavy Duty Storage Box - 870L / Black | B16: Mr Paul Dandy | C16: 1063991246-A | D16: 17/05/2026 | E16: 1 | F16: Out of stock, customer happy to accept exchange for 870L Taupe, stock updated -1 870L Black and +1 870L Taupe
A17: Heavy Duty Storage Box - 870L / Black | B17: Nick Sisso | C17: 1063995257-A | D17: 17/05/2026 | E17: 2 | F17: Out of stock, customer happy to accept exchange for 870L Taupe, stock updated -2 870L Black and +2 870L Taupe
A18: Heavy Duty Storage Box - 870L / Black | B18: Neil Christie | C18: 1064006193-A | D18: 17/05/2026 | E18: 1 | F18: Out of stock, customer happy to accept exchange for 870L Taupe, stock updated -1 870L Black and +1 870L Taupe

Sheet JL FORECAST
B1: Sales Forecast | C1: Buy | E1: FEBRUARY | F1: MARCH | G1: APRIL | H1: MAY | I1: JUNE | J1: JULY | K1: AUGUST | L1: SEPTEMBER | M1: TOTAL SALES | N1: % OF BUY
A2: 3M D Hydraulic parasol with base | B2: 50 | C2: 100 | E2: 0 | F2: 2 | G2: 4 | H2: 10 | I2: 10 | J2: 10 | K2: 8 | L2: 2 | M2: =E2+F2+G2+H2+I2+J2+K2+L2 | N2: =M2/C2
A3: STOR 693L | B3: 40 | C3: 60 | E3: 2 | F3: 4 | G3: 6 | H3: 6 | I3: 6 | J3: 6 | K3: 6 | L3: 4 | M3: =E3+F3+G3+H3+I3+J3+K3+L3 | N3: =M3/C3
A4: STOR 1067L | B4: 60 | C4: 60 | E4: 3 | F4: 5 | G4: 5 | H4: 5 | I4: 8 | J4: 8 | K4: 8 | L4: 4 | M4: =E4+F4+G4+H4+I4+J4+K4+L4 | N4: =M4/C4
A5: 270L recycled box | B5: 150 | C5: 320 | E5: 12 | F5: 25 | G5: 32 | H5: 32 | I5: 32 | J5: 32 | K5: 20 | L5: 20 | M5: =E5+F5+G5+H5+I5+J5+K5+L5 | N5: =M5/C5
A6: 450L recycled box | B6: 250 | C6: 225 | E6: 10 | F6: 15 | G6: 32 | H6: 32 | I6: 32 | J6: 32 | K6: 25 | L6: 25 | M6: =E6+F6+G6+H6+I6+J6+K6+L6 | N6: =M6/C6
A7: 680L recycled box | B7: 200 | C7: 180 | E7: 8 | F7: 15 | G7: 15 | H7: 25 | I7: 25 | J7: 25 | K7: 20 | L7: 20 | M7: =E7+F7+G7+H7+I7+J7+K7+L7 | N7: =M7/C7
A8: 870L recycled box | B8: 150 | C8: 100 | E8: 4 | F8: 8 | G8: 10 | H8: 10 | I8: 10 | J8: 8 | K8: 8 | L8: 8 | M8: =E8+F8+G8+H8+I8+J8+K8+L8 | N8: =M8/C8
A9: 980L recycled box | B9: 100 | C9: 100 | E9: 2 | F9: 4 | G9: 8 | H9: 8 | I9: 8 | J9: 12 | K9: 12 | L9: 8 | M9: =E9+F9+G9+H9+I9+J9+K9+L9 | N9: =M9/C9
A10: 3 x 3 with sides with side walls | B10: 60 | C10: 100 | E10: 2 | F10: 6 | G10: 6 | H10: 8 | I10: 12 | J10: 12 | K10: 8 | L10: 4 | M10: =E10+F10+G10+H10+I10+J10+K10+L10 | N10: =M10/C10
A11: TOTALS | B11: =SUM(B2:B10) | C11: =SUM(C2:C10) | E11: HJ849-D | F11: J2
C13: HJ DESPATCH | E13: =E2+E3+E4+E10 | F13: =F2+F3+F4+F10 | G13: =G2+G3+G4+G10 | H13: =H2+H3+H4+H10 | I13: =I2+I3+I4+I10 | J13: =J2+J3+J4+J10 | K13: =K2+K3+K4+K10 | L13: =L2+L3+L4+L10 | M13: =M2+M3+M4+M10
C15: AVERAGE WEEKLY | E15: =E13/4 | F15: =F13/4 | G15: =G13/4 | H15: =H13/4 | I15: =I13/4 | J15: =J13/4 | K15: =K13/4 | L15: =L13/4
C17: KINETIC DESPATCH | E17: =E5+E6+E7+E8+E9 | F17: =F5+F6+F7+F8+F9 | G17: =G5+G6+G7+G8+G9 | H17: =H5+H6+H7+H8+H9 | I17: =I5+I6+I7+I8+I9 | J17: =J5+J6+J7+J8+J9 | K17: =K5+K6+K7+K8+K9 | L17: =L5+L6+L7+L8+L9
C19: AVERAGE WEEKLY | E19: =E17/4 | F19: =F17/4 | G19: =G17/4 | H19: =H17/4 | I19: =I17/4 | J19: =J17/4 | K19: =K17/4 | L19: =L17/4
E21: SALES EX VAT
D22: cp | E22: FEBRUARY | F22: MARCH | G22: APRIL | H22: MAY | I22: JUNE | J22: JULY | K22: AUGUST | L22: SEPTEMBER
B23: 3M D Hydraulic parasol with base | D23: 119.08 | E23: =$D$23*E2 | F23: =$D$23*F2 | G23: =$D$23*G2 | H23: =$D$23*H2 | I23: =$D$23*I2 | J23: =$D$23*J2 | K23: =$D$23*K2 | L23: =$D$23*L2
B24: STOR 693L | D24: 207.38 | E24: =$D$23*E3 | F24: =$D$23*F3 | G24: =$D$23*G3 | H24: =$D$23*H3 | I24: =$D$23*I3 | J24: =$D$23*J3 | K24: =$D$23*K3 | L24: =$D$23*L3
B25: STOR 1067L | D25: 246.95 | E25: =$D$23*E4 | F25: =$D$23*F4 | G25: =$D$23*G4 | H25: =$D$23*H4 | I25: =$D$23*I4 | J25: =$D$23*J4 | K25: =$D$23*K4 | L25: =$D$23*L4
B26: 270L recycled box | D26: 34.99 | E26: =$D$23*E5 | F26: =$D$23*F5 | G26: =$D$23*G5 | H26: =$D$23*H5 | I26: =$D$23*I5 | J26: =$D$23*J5 | K26: =$D$23*K5 | L26: =$D$23*L5
B27: 450L recycled box | D27: 61.45 | E27: =$D$23*E6 | F27: =$D$23*F6 | G27: =$D$23*G6 | H27: =$D$23*H6 | I27: =$D$23*I6 | J27: =$D$23*J6 | K27: =$D$23*K6 | L27: =$D$23*L6
B28: 680L recycled box | D28: 77.67 | E28: =$D$23*E7 | F28: =$D$23*F7 | G28: =$D$23*G7 | H28: =$D$23*H7 | I28: =$D$23*I7 | J28: =$D$23*J7 | K28: =$D$23*K7 | L28: =$D$23*L7
B29: 870L recycled box | D29: 94.47 | E29: =$D$23*E8 | F29: =$D$23*F8 | G29: =$D$23*G8 | H29: =$D$23*H8 | I29: =$D$23*I8 | J29: =$D$23*J8 | K29: =$D$23*K8 | L29: =$D$23*L8
B30: 980L recycled box | D30: 102.14 | E30: =$D$23*E9 | F30: =$D$23*F9 | G30: =$D$23*G9 | H30: =$D$23*H9 | I30: =$D$23*I9 | J30: =$D$23*J9 | K30: =$D$23*K9 | L30: =$D$23*L9
B31: 3 x 3 with sides with side walls | D31: 99.4 | E31: =$D$23*E10 | F31: =$D$23*F10 | G31: =$D$23*G10 | H31: =$D$23*H10 | I31: =$D$23*I10 | J31: =$D$23*J10 | K31: =$D$23*K10 | L31: =$D$23*L10
E32: =SUM(E23:E31) | F32: =SUM(F23:F31) | G32: =SUM(G23:G31) | H32: =SUM(H23:H31) | I32: =SUM(I23:I31) | J32: =SUM(J23:J31) | K32: =SUM(K23:K31) | L32: =SUM(L23:L31)
